Metal device set to: Apple M1

systemMemory: 8.00 GB
maxCacheSize: 2.67 GB

2023-07-09 20:13:36.305591: I tensorflow/core/common_runtime/pluggable_device/pluggable_device_factory.cc:306] Could not identify NUMA node of platform GPU ID 0, defaulting to 0. Your kernel may not have been built with NUMA support.
2023-07-09 20:13:36.305613: I tensorflow/core/common_runtime/pluggable_device/pluggable_device_factory.cc:272] Created TensorFlow device (/job:localhost/replica:0/task:0/device:GPU:0 with 0 MB memory) -> physical PluggableDevice (device: 0, name: METAL, pci bus id: <undefined>)
Run: 0, exploration: 1.0, score: 19
state: (array([-0.00125746, -0.0249122 ,  0.04350457, -0.02835035], dtype=float32), {})
2023-07-09 20:13:36.413863: W tensorflow/tsl/platform/profile_utils/cpu_utils.cc:128] Failed to get CPU frequency: 0 Hz
WARNING:tensorflow:Model was constructed with shape (None, 4) for input KerasTensor(type_spec=TensorSpec(shape=(None, 4), dtype=tf.float32, name='dense_input'), name='dense_input', description="created by layer 'dense_input'"), but it was called on an input with incompatible shape (None,).
Traceback (most recent call last):
  File "/Users/mitchell/Desktop/comp-methods/physics/cartpole/cartpole.py", line 108, in <module>
    cartpole_dqn()
  File "/Users/mitchell/Desktop/comp-methods/physics/cartpole/cartpole.py", line 96, in cartpole_dqn
    dqn_solver.experience_replay()
  File "/Users/mitchell/Desktop/comp-methods/physics/cartpole/cartpole.py", line 55, in experience_replay
    q_update = (reward + GAMMA * np.amax(self.model.predict(state_next)[0]))
  File "/Users/mitchell/opt/miniconda3/lib/python3.9/site-packages/keras/utils/traceback_utils.py", line 70, in error_handler
    raise e.with_traceback(filtered_tb) from None
  File "/var/folders/bp/z8s1cn695yndmdw07kpl9yzc0000gn/T/__autograph_generated_filei75btgl9.py", line 15, in tf__predict_function
    retval_ = ag__.converted_call(ag__.ld(step_function), (ag__.ld(self), ag__.ld(iterator)), None, fscope)
ValueError: in user code:

    File "/Users/mitchell/opt/miniconda3/lib/python3.9/site-packages/keras/engine/training.py", line 2137, in predict_function  *
        return step_function(self, iterator)
    File "/Users/mitchell/opt/miniconda3/lib/python3.9/site-packages/keras/engine/training.py", line 2123, in step_function  **
        outputs = model.distribute_strategy.run(run_step, args=(data,))
    File "/Users/mitchell/opt/miniconda3/lib/python3.9/site-packages/keras/engine/training.py", line 2111, in run_step  **
        outputs = model.predict_step(data)
    File "/Users/mitchell/opt/miniconda3/lib/python3.9/site-packages/keras/engine/training.py", line 2079, in predict_step
        return self(x, training=False)
    File "/Users/mitchell/opt/miniconda3/lib/python3.9/site-packages/keras/utils/traceback_utils.py", line 70, in error_handler
        raise e.with_traceback(filtered_tb) from None
    File "/Users/mitchell/opt/miniconda3/lib/python3.9/site-packages/keras/engine/input_spec.py", line 250, in assert_input_compatibility
        raise ValueError(

    ValueError: Exception encountered when calling layer 'sequential' (type Sequential).
    
    Input 0 of layer "dense" is incompatible with the layer: expected min_ndim=2, found ndim=1. Full shape received: (None,)
    
    Call arguments received by layer 'sequential' (type Sequential):
      • inputs=tf.Tensor(shape=(None,), dtype=float32)
      • training=False
      • mask=None

/Users/mitchell/opt/miniconda3/lib/python3.9/site-packages/gymnasium/wrappers/monitoring/video_recorder.py:182: UserWarning: WARN: Unable to save last video! Did you call close()?